2023-02-24 17:05:07,999 (ERROR) - 241 - django.request - Cannot resolve keyword 'date' into field. Choices are: id, is_active, mouvements, name, user, user_id: /api/camions/
rest_framework.exceptions.APIException: Cannot resolve keyword 'date' into field. Choices are: id, is_active, mouvements, name, user, user_id
2023-02-24 17:07:19,884 (ERROR) - 241 - django.request - Internal Server Error: /api/camions/
Traceback (most recent call last):
  File "/Users/pilachrist/PycharmProjects/targetProject/venv/lib/python3.9/site-packages/rest_framework/views.py", line 506, in dispatch
    response = handler(request, *args, **kwargs)
  File "/Users/pilachrist/PycharmProjects/targetProject/venv/lib/python3.9/site-packages/rest_framework/mixins.py", line 38, in list
    queryset = self.filter_queryset(self.get_queryset())
  File "/Users/pilachrist/PycharmProjects/targetProject/tracker/views/camions/camions_v.py", line 19, in get_queryset
    query_set = Camions.objects.get(date=22)
  File "/Users/pilachrist/PycharmProjects/targetProject/venv/lib/python3.9/site-packages/django/db/models/manager.py", line 85, in manager_method
    return getattr(self.get_queryset(), name)(*args, **kwargs)
  File "/Users/pilachrist/PycharmProjects/targetProject/venv/lib/python3.9/site-packages/django/db/models/query.py", line 636, in get
    clone = self._chain() if self.query.combinator else self.filter(*args, **kwargs)
  File "/Users/pilachrist/PycharmProjects/targetProject/venv/lib/python3.9/site-packages/django/db/models/query.py", line 1421, in filter
    return self._filter_or_exclude(False, args, kwargs)
  File "/Users/pilachrist/PycharmProjects/targetProject/venv/lib/python3.9/site-packages/django/db/models/query.py", line 1439, in _filter_or_exclude
    clone._filter_or_exclude_inplace(negate, args, kwargs)
  File "/Users/pilachrist/PycharmProjects/targetProject/venv/lib/python3.9/site-packages/django/db/models/query.py", line 1446, in _filter_or_exclude_inplace
    self._query.add_q(Q(*args, **kwargs))
  File "/Users/pilachrist/PycharmProjects/targetProject/venv/lib/python3.9/site-packages/django/db/models/sql/query.py", line 1532, in add_q
    clause, _ = self._add_q(q_object, self.used_aliases)
  File "/Users/pilachrist/PycharmProjects/targetProject/venv/lib/python3.9/site-packages/django/db/models/sql/query.py", line 1562, in _add_q
    child_clause, needed_inner = self.build_filter(
  File "/Users/pilachrist/PycharmProjects/targetProject/venv/lib/python3.9/site-packages/django/db/models/sql/query.py", line 1407, in build_filter
    lookups, parts, reffed_expression = self.solve_lookup_type(arg)
  File "/Users/pilachrist/PycharmProjects/targetProject/venv/lib/python3.9/site-packages/django/db/models/sql/query.py", line 1217, in solve_lookup_type
    _, field, _, lookup_parts = self.names_to_path(lookup_splitted, self.get_meta())
  File "/Users/pilachrist/PycharmProjects/targetProject/venv/lib/python3.9/site-packages/django/db/models/sql/query.py", line 1709, in names_to_path
    raise FieldError(
django.core.exceptions.FieldError: Cannot resolve keyword 'date' into field. Choices are: id, is_active, mouvements, name, user, user_id

During handling of the above exception, another exception occurred:

Traceback (most recent call last):
  File "/Users/pilachrist/PycharmProjects/targetProject/venv/lib/python3.9/site-packages/django/utils/module_loading.py", line 30, in import_string
    return cached_import(module_path, class_name)
  File "/Users/pilachrist/PycharmProjects/targetProject/venv/lib/python3.9/site-packages/django/utils/module_loading.py", line 16, in cached_import
    return getattr(module, class_name)
AttributeError: module 'target' has no attribute 'DFRExceptionHandler'

The above exception was the direct cause of the following exception:

Traceback (most recent call last):
  File "/Users/pilachrist/PycharmProjects/targetProject/venv/lib/python3.9/site-packages/rest_framework/settings.py", line 177, in import_from_string
    return import_string(val)
  File "/Users/pilachrist/PycharmProjects/targetProject/venv/lib/python3.9/site-packages/django/utils/module_loading.py", line 32, in import_string
    raise ImportError(
ImportError: Module "target" does not define a "DFRExceptionHandler" attribute/class

During handling of the above exception, another exception occurred:

Traceback (most recent call last):
  File "/Users/pilachrist/PycharmProjects/targetProject/venv/lib/python3.9/site-packages/django/core/handlers/exception.py", line 56, in inner
    response = get_response(request)
  File "/Users/pilachrist/PycharmProjects/targetProject/venv/lib/python3.9/site-packages/django/core/handlers/base.py", line 197, in _get_response
    response = wrapped_callback(request, *callback_args, **callback_kwargs)
  File "/Users/pilachrist/PycharmProjects/targetProject/venv/lib/python3.9/site-packages/django/views/decorators/csrf.py", line 55, in wrapped_view
    return view_func(*args, **kwargs)
  File "/Users/pilachrist/PycharmProjects/targetProject/venv/lib/python3.9/site-packages/rest_framework/viewsets.py", line 125, in view
    return self.dispatch(request, *args, **kwargs)
  File "/Users/pilachrist/PycharmProjects/targetProject/venv/lib/python3.9/site-packages/rest_framework/views.py", line 509, in dispatch
    response = self.handle_exception(exc)
  File "/Users/pilachrist/PycharmProjects/targetProject/venv/lib/python3.9/site-packages/rest_framework/views.py", line 466, in handle_exception
    response = exception_handler(exc, context)
  File "/Users/pilachrist/PycharmProjects/targetProject/venv/lib/python3.9/site-packages/drf_standardized_errors/handler.py", line 23, in exception_handler
    exception_handler_class = package_settings.EXCEPTION_HANDLER_CLASS
  File "/Users/pilachrist/PycharmProjects/targetProject/venv/lib/python3.9/site-packages/drf_standardized_errors/settings.py", line 48, in __getattr__
    val = perform_import(val, attr)
  File "/Users/pilachrist/PycharmProjects/targetProject/venv/lib/python3.9/site-packages/rest_framework/settings.py", line 166, in perform_import
    return import_from_string(val, setting_name)
  File "/Users/pilachrist/PycharmProjects/targetProject/venv/lib/python3.9/site-packages/rest_framework/settings.py", line 180, in import_from_string
    raise ImportError(msg)
ImportError: Could not import 'target.DFRExceptionHandler' for API setting 'EXCEPTION_HANDLER_CLASS'. ImportError: Module "target" does not define a "DFRExceptionHandler" attribute/class.
2023-02-24 17:07:33,695 (ERROR) - 241 - django.request - Internal Server Error: /api/camions/
Traceback (most recent call last):
  File "/Users/pilachrist/PycharmProjects/targetProject/venv/lib/python3.9/site-packages/rest_framework/views.py", line 506, in dispatch
    response = handler(request, *args, **kwargs)
  File "/Users/pilachrist/PycharmProjects/targetProject/venv/lib/python3.9/site-packages/rest_framework/mixins.py", line 38, in list
    queryset = self.filter_queryset(self.get_queryset())
  File "/Users/pilachrist/PycharmProjects/targetProject/tracker/views/camions/camions_v.py", line 19, in get_queryset
    query_set = Camions.objects.get(date=22)
  File "/Users/pilachrist/PycharmProjects/targetProject/venv/lib/python3.9/site-packages/django/db/models/manager.py", line 85, in manager_method
    return getattr(self.get_queryset(), name)(*args, **kwargs)
  File "/Users/pilachrist/PycharmProjects/targetProject/venv/lib/python3.9/site-packages/django/db/models/query.py", line 636, in get
    clone = self._chain() if self.query.combinator else self.filter(*args, **kwargs)
  File "/Users/pilachrist/PycharmProjects/targetProject/venv/lib/python3.9/site-packages/django/db/models/query.py", line 1421, in filter
    return self._filter_or_exclude(False, args, kwargs)
  File "/Users/pilachrist/PycharmProjects/targetProject/venv/lib/python3.9/site-packages/django/db/models/query.py", line 1439, in _filter_or_exclude
    clone._filter_or_exclude_inplace(negate, args, kwargs)
  File "/Users/pilachrist/PycharmProjects/targetProject/venv/lib/python3.9/site-packages/django/db/models/query.py", line 1446, in _filter_or_exclude_inplace
    self._query.add_q(Q(*args, **kwargs))
  File "/Users/pilachrist/PycharmProjects/targetProject/venv/lib/python3.9/site-packages/django/db/models/sql/query.py", line 1532, in add_q
    clause, _ = self._add_q(q_object, self.used_aliases)
  File "/Users/pilachrist/PycharmProjects/targetProject/venv/lib/python3.9/site-packages/django/db/models/sql/query.py", line 1562, in _add_q
    child_clause, needed_inner = self.build_filter(
  File "/Users/pilachrist/PycharmProjects/targetProject/venv/lib/python3.9/site-packages/django/db/models/sql/query.py", line 1407, in build_filter
    lookups, parts, reffed_expression = self.solve_lookup_type(arg)
  File "/Users/pilachrist/PycharmProjects/targetProject/venv/lib/python3.9/site-packages/django/db/models/sql/query.py", line 1217, in solve_lookup_type
    _, field, _, lookup_parts = self.names_to_path(lookup_splitted, self.get_meta())
  File "/Users/pilachrist/PycharmProjects/targetProject/venv/lib/python3.9/site-packages/django/db/models/sql/query.py", line 1709, in names_to_path
    raise FieldError(
django.core.exceptions.FieldError: Cannot resolve keyword 'date' into field. Choices are: id, is_active, mouvements, name, user, user_id

During handling of the above exception, another exception occurred:

Traceback (most recent call last):
  File "/Users/pilachrist/PycharmProjects/targetProject/venv/lib/python3.9/site-packages/django/utils/module_loading.py", line 25, in import_string
    module_path, class_name = dotted_path.rsplit(".", 1)
ValueError: not enough values to unpack (expected 2, got 1)

The above exception was the direct cause of the following exception:

Traceback (most recent call last):
  File "/Users/pilachrist/PycharmProjects/targetProject/venv/lib/python3.9/site-packages/rest_framework/settings.py", line 177, in import_from_string
    return import_string(val)
  File "/Users/pilachrist/PycharmProjects/targetProject/venv/lib/python3.9/site-packages/django/utils/module_loading.py", line 27, in import_string
    raise ImportError("%s doesn't look like a module path" % dotted_path) from err
ImportError: DFRExceptionHandler doesn't look like a module path

During handling of the above exception, another exception occurred:

Traceback (most recent call last):
  File "/Users/pilachrist/PycharmProjects/targetProject/venv/lib/python3.9/site-packages/django/core/handlers/exception.py", line 56, in inner
    response = get_response(request)
  File "/Users/pilachrist/PycharmProjects/targetProject/venv/lib/python3.9/site-packages/django/core/handlers/base.py", line 197, in _get_response
    response = wrapped_callback(request, *callback_args, **callback_kwargs)
  File "/Users/pilachrist/PycharmProjects/targetProject/venv/lib/python3.9/site-packages/django/views/decorators/csrf.py", line 55, in wrapped_view
    return view_func(*args, **kwargs)
  File "/Users/pilachrist/PycharmProjects/targetProject/venv/lib/python3.9/site-packages/rest_framework/viewsets.py", line 125, in view
    return self.dispatch(request, *args, **kwargs)
  File "/Users/pilachrist/PycharmProjects/targetProject/venv/lib/python3.9/site-packages/rest_framework/views.py", line 509, in dispatch
    response = self.handle_exception(exc)
  File "/Users/pilachrist/PycharmProjects/targetProject/venv/lib/python3.9/site-packages/rest_framework/views.py", line 466, in handle_exception
    response = exception_handler(exc, context)
  File "/Users/pilachrist/PycharmProjects/targetProject/venv/lib/python3.9/site-packages/drf_standardized_errors/handler.py", line 23, in exception_handler
    exception_handler_class = package_settings.EXCEPTION_HANDLER_CLASS
  File "/Users/pilachrist/PycharmProjects/targetProject/venv/lib/python3.9/site-packages/drf_standardized_errors/settings.py", line 48, in __getattr__
    val = perform_import(val, attr)
  File "/Users/pilachrist/PycharmProjects/targetProject/venv/lib/python3.9/site-packages/rest_framework/settings.py", line 166, in perform_import
    return import_from_string(val, setting_name)
  File "/Users/pilachrist/PycharmProjects/targetProject/venv/lib/python3.9/site-packages/rest_framework/settings.py", line 180, in import_from_string
    raise ImportError(msg)
ImportError: Could not import 'DFRExceptionHandler' for API setting 'EXCEPTION_HANDLER_CLASS'. ImportError: DFRExceptionHandler doesn't look like a module path.
